<robot name="dtw_robot" xmlns:xacro="http://ros.org/wiki/xacro">
  <material name="gray">
    <color rgba="0.5 0.5 0.5 2.5"/>
  </material>
  <material name="red">
    <color rgba="1.0 0.0 0.0 2.5"/>
  </material>

  <xacro:macro name="wheel_macro" params="parent prefix xyz">
    <joint name="${prefix}_joint" type="continuous">
      <origin xyz="${xyz}" rpy="${radians(-90)} 0 0"/>
      <parent link="${parent}"/>
      <child  link="${prefix}_link"/>
      <axis xyz="0 0 1" />
    </joint>
    <link name="${prefix}_link">
      <visual>
        <geometry>
          <cylinder radius="0.05" length="0.02" />
        </geometry>
        <material name="red"/>
      </visual>
    </link>
  </xacro:macro> 


  <link name="world"/>

  <joint name="base_joint" type="floating">
    <parent link="world"/>
    <child  link="base_link"/>
  </joint>

  <link name="base_link"/>

  <joint name="body_joint" type="fixed">
    <parent link="base_link"/>
    <child  link="body_link"/>
    <origin xyz="-0.07 0 0.07" rpy="0 0 0"/>
  </joint>
	
  <link name="laser">
    <visual>
      <origin xyz="0 0 -0.1" rpy="0 0 0" />
      <geometry>
        <box size="0.03 0.03 0.2" />
      </geometry>
      <material name="gray" />
    </visual>
  </link>

  <joint name="laser_joint" type="fixed">
    <parent link="base_link"/>
    <child  link="laser"/>
    <origin xyz="0 0 0.2" rpy="0 0 0"/>

  </joint>

  <link name="body_link">
    <visual>
      <origin xyz="0 0 0" rpy="0 0 0" />
      <geometry>
        <box size="0.24 0.18 0.06" />
      </geometry>
      <material name="gray" />
    </visual>
  </link>

  <xacro:wheel_macro prefix="left_wheel"  parent="base_link" xyz="0 0.1 0.05"/>
  <xacro:wheel_macro prefix="right_wheel" parent="base_link" xyz="0 -0.1 0.05"/>

  <joint name="ball_joint" type="fixed">
    <parent link="base_link"/>
    <child  link="ball_link"/>
    <origin xyz="-0.14 0 0.04" rpy="0 0 0"/>
  </joint>
  <link name="ball_link">
   <visual>
     <origin xyz="0 0 0" rpy="0 0 0" />
     <geometry>
       <sphere radius="0.04" />
     </geometry>
     <material name="gray" />
   </visual>
  </link>
</robot>
